Workbook

Sheet Parameters-FG
A1: Site | B1: Production Line | C1: Line TRP | D1: Part No. | E1: Description | F1: Mini Production QTY(MPQ) | G1: Cycle time | H1: Target Stock | I1: No. of hours/shift | J1: No. of shift/day | K1: Output per shift | L1: Headcount
A2: WL | B2: PGLINKAGE | C2: 0.71 | D2: WA14208 | E2: DX11电机连杆总成 | F2: 48 | G2: =VLOOKUP(D2,'WL CT '!A:C,3,0) | H2: 0 | I2: 8 | J2: 3 | K2: =ROUNDUP(3600/G2*C2*I2,0) | L2: 3
A3: WL | B3: PGLINKAGE | C3: 0.71 | D3: WAB6404 | E3: E371 A1 传动杆总成 | F3: 72 | G3: =VLOOKUP(D3,'WL CT '!A:C,3,0) | H3: 0 | I3: 8 | J3: 3 | K3: =ROUNDUP(3600/G3*C3*I3,0) | L3: 3
A4: WL | B4: PGLINKAGE | C4: 0.71 | D4: WB35356 | E4: 930B传动杆总成 | F4: 60 | G4: =VLOOKUP(D4,'WL CT '!A:C,3,0) | H4: 0 | I4: 8 | J4: 3 | K4: =ROUNDUP(3600/G4*C4*I4,0) | L4: 3
A5: WL | B5: PGLINKAGE | C5: 0.71 | D5: WB80510 | E5: CX11 LHD传动杆总成（新） | F5: 48 | G5: =VLOOKUP(D5,'WL CT '!A:C,3,0) | H5: 0 | I5: 8 | J5: 3 | K5: =ROUNDUP(3600/G5*C5*I5,0) | L5: 3
A6: WL | B6: PGLINKAGE | C6: 0.71 | D6: WC07674 | E6: CM2E 电机及连杆机构 | F6: 72 | G6: =VLOOKUP(D6,'WL CT '!A:C,3,0) | H6: 0 | I6: 8 | J6: 3 | K6: =ROUNDUP(3600/G6*C6*I6,0) | L6: 3
A7: WL | B7: PGLINKAGE | C7: 0.71 | D7: WD48696 | E7: L743 传动杆总成 | F7: 60 | G7: =VLOOKUP(D7,'WL CT '!A:C,3,0) | H7: 0 | I7: 8 | J7: 3 | K7: =ROUNDUP(3600/G7*C7*I7,0) | L7: 3
A8: WL | B8: PGLINKAGE | C8: 0.71 | D8: WD59238 | E8: E371传动杆总成 | F8: 48 | G8: =VLOOKUP(D8,'WL CT '!A:C,3,0) | H8: 0 | I8: 8 | J8: 3 | K8: =ROUNDUP(3600/G8*C8*I8,0) | L8: 3
A9: WL | B9: PGLINKAGE | C9: 0.71 | D9: W144813S | E9: Geely DCY11前雨刮电机传动杆总成 (备件) | F9: 72 | G9: =VLOOKUP(D9,'WL CT '!A:C,3,0) | H9: 0 | I9: 8 | J9: 3 | K9: =ROUNDUP(3600/G9*C9*I9,0) | L9: 3
A10: WL | B10: PGLINKAGE | C10: 0.71 | D10: W000076959VA | E10: 领克 01&03 前雨刮电机传动杆 | F10: 60 | G10: =VLOOKUP(D10,'WL CT '!A:C,3,0) | H10: 0 | I10: 8 | J10: 3 | K10: =ROUNDUP(3600/G10*C10*I10,0) | L10: 3
A11: WL | B11: PGLINKAGE | C11: 0.71 | D11: W243255S | E11: 宝马欧洲G38前雨刮电机传动杆成品 (备件) | F11: 48 | G11: =VLOOKUP(D11,'WL CT '!A:C,3,0) | H11: 0 | I11: 8 | J11: 3 | K11: =ROUNDUP(3600/G11*C11*I11,0) | L11: 3
A12: WL | B12: PGLINKAGE | C12: 0.71 | D12: WA14208S | E12: 吉利DX11左驾前雨刮电机传动杆 (备件) | F12: 72 | G12: =VLOOKUP(D12,'WL CT '!A:C,3,0) | H12: 0 | I12: 8 | J12: 3 | K12: =ROUNDUP(3600/G12*C12*I12,0) | L12: 3
A13: WL | B13: PGLINKAGE | C13: 0.71 | D13: WD48696S | E13: 领克L743左驾前雨刮电机传动杆总成 (备件) | F13: 60 | G13: =VLOOKUP(D13,'WL CT '!A:C,3,0) | H13: 0 | I13: 8 | J13: 3 | K13: =ROUNDUP(3600/G13*C13*I13,0) | L13: 3
... A18: WL | B18: PGLINKAGE | C18: 0.71 | D18: WCA1894 | E18: Chery KP31 LHD 传动杆 | F18: 60 | G18: =VLOOKUP(D18,'WL CT '!A:C,3,0) | H18: 0 | I18: 8 | J18: 3 | K18: =ROUNDUP(3600/G18*C18*I18,0) | L18: 3
A19: SY38 | B19: PU07 | C19: 0.85 | D19: L755390S | E19: B9 Low Fender L | F19: 70 | G19: 35 | H19: 0 | I19: 12 | J19: 2 | K19: =ROUNDUP(3600/G19*C19*I19,0) | L19: 12
A20: SY38 | B20: PU07 | C20: 0.85 | D20: L755392S | E20: B9 Low Fender R | F20: 70 | G20: 35 | H20: 0 | I20: 12 | J20: 2 | K20: =ROUNDUP(3600/G20*C20*I20,0) | L20: 12
A21: SY38 | B21: PU07 | C21: 0.85 | D21: LA96403S | E21: B9RL Fender lamp Left side OEM | F21: 70 | G21: 35 | H21: 0 | I21: 12 | J21: 2 | K21: =ROUNDUP(3600/G21*C21*I21,0) | L21: 12
A22: SY38 | B22: PU07 | C22: 0.85 | D22: LA96404S | E22: B9RL Fender lamp Right side OEM | F22: 70 | G22: 35 | H22: 0 | I22: 12 | J22: 2 | K22: =ROUNDUP(3600/G22*C22*I22,0) | L22: 12
A23: SY38 | B23: PU07 | C23: 0.85 | D23: LA83453S | E23: B9 Low Trunk | F23: 24 | G23: 70 | H23: 0 | I23: 12 | J23: 2 | K23: =ROUNDUP(3600/G23*C23*I23,0) | L23: 12
A24: SY38 | B24: PU07 | C24: 0.85 | D24: L755548S | E24: B9 High Trunk | F24: 24 | G24: 70 | H24: 0 | I24: 12 | J24: 2 | K24: =ROUNDUP(3600/G24*C24*I24,0) | L24: 12
A25: SY38 | B25: PU07 | C25: 0.85 | D25: LA96445S | E25: B9RL TRUNK High OEM | F25: 24 | G25: 70 | H25: 0 | I25: 12 | J25: 2 | K25: =ROUNDUP(3600/G25*C25*I25,0) | L25: 12
A26: SY38 | B26: PU22 | C26: 0.7 | D26: LCC4666ZO04 | E26: BMW NA8 翼灯总成左 | F26: 24 | G26: 45 | H26: 0 | I26: 12 | J26: 2 | K26: =ROUNDUP(3600/G26*C26*I26,0) | L26: 12
A27: SY38 | B27: PU22 | C27: 0.7 | D27: LCC4690ZO04 | E27: BMW NA8 翼灯总成右 | F27: 24 | G27: 45 | H27: 0 | I27: 12 | J27: 2 | K27: =ROUNDUP(3600/G27*C27*I27,0) | L27: 12
A28: SY38 | B28: PU22 | C28: 0.7 | D28: LCC4710ZN04 | E28: BMW NA8 箱灯总成左 | F28: 24 | G28: 50 | H28: 0 | I28: 12 | J28: 2 | K28: =ROUNDUP(3600/G28*C28*I28,0) | L28: 15
A29: SY38 | B29: PU22 | C29: 0.7 | D29: LCC4725ZN04 | E29: BMW NA8 箱灯总成右 | F29: 24 | G29: 50 | H29: 0 | I29: 12 | J29: 2 | K29: =ROUNDUP(3600/G29*C29*I29,0) | L29: 15
A42: 挑一个成品和半成品，把他们所在的产线的所有物料都列在成品和半成品表中，还有BOM清单

Sheet Parameters-SFN
A1: Site | B1: Production Line | C1: Line TRP | D1: Part No. | E1: Description | F1: Mini Production QTY(MPQ) | G1: Cycle time(S) | H1: Target Stock(days) | I1: 生产提前期(days） | J1: Scrap rate(%) | K1: No. of hours/shift | L1: No. of shift/day | M1: Output per shift | N1: Head count | O1: Max stock
A2: WL | B2: 轴套6 | C2: 0.85 | D2: W000061536 | E2: G38 DS轴套分总成 | F2: 100 | G2: =VLOOKUP(D2,'WL CT '!A:C,3,0) | H2: 0 | I2: 1 | J2: 0.03 | K2: 8 | L2: 3 | M2: =3600/G2*C2*K2
A3: WL | B3: 轴套6 | C3: 0.85 | D3: W000061541 | E3: G38 PS轴套分总成 | F3: 100 | G3: =VLOOKUP(D3,'WL CT '!A:C,3,0) | H3: 0 | I3: 1 | J3: 0.03 | K3: 8 | L3: 3 | M3: =3600/G3*C3*K3
A4: WL | B4: 轴套6 | C4: 0.85 | D4: WA14222 | E4: DX11 DS 轴套分总成 | F4: 100 | G4: =VLOOKUP(D4,'WL CT '!A:C,3,0) | H4: 0 | I4: 1 | J4: 0.03 | K4: 8 | L4: 3 | M4: =3600/G4*C4*K4
A5: WL | B5: 轴套6 | C5: 0.85 | D5: WA14229 | E5: DX11 PS 轴套分总成 | F5: 100 | G5: =VLOOKUP(D5,'WL CT '!A:C,3,0) | H5: 0 | I5: 1 | J5: 0.03 | K5: 8 | L5: 3 | M5: =3600/G5*C5*K5
A6: WL | B6: 轴套6 | C6: 0.85 | D6: WAB6407 | E6: E371 A1 DS 轴套分总成 | F6: 100 | G6: =VLOOKUP(D6,'WL CT '!A:C,3,0) | H6: 0 | I6: 1 | J6: 0.03 | K6: 8 | L6: 3 | M6: =3600/G6*C6*K6
A7: WL | B7: 轴套6 | C7: 0.85 | D7: WAB6412 | E7: E371 A1 PS 轴套分总成 | F7: 100 | G7: =VLOOKUP(D7,'WL CT '!A:C,3,0) | H7: 0 | I7: 1 | J7: 0.03 | K7: 8 | L7: 3 | M7: =3600/G7*C7*K7
A8: WL | B8: 轴套6 | C8: 0.85 | D8: WC84833 | E8: 930B DS 轴套分总成 | F8: 100 | G8: =VLOOKUP(D8,'WL CT '!A:C,3,0) | H8: 0 | I8: 1 | J8: 0.03 | K8: 8 | L8: 3 | M8: =3600/G8*C8*K8
A9: WL | B9: 轴套6 | C9: 0.85 | D9: WC52036 | E9: 930B PS 轴套分总成 | F9: 100 | G9: =VLOOKUP(D9,'WL CT '!A:C,3,0) | H9: 0 | I9: 1 | J9: 0.03 | K9: 8 | L9: 3 | M9: =3600/G9*C9*K9
A10: WL | B10: 轴套6 | C10: 0.85 | D10: WC07786 | E10: CM2E DS 轴套分总成 | F10: 100 | G10: =VLOOKUP(D10,'WL CT '!A:C,3,0) | H10: 0 | I10: 1 | J10: 0.03 | K10: 8 | L10: 3 | M10: =3600/G10*C10*K10
A11: WL | B11: 轴套6 | C11: 0.85 | D11: WC08355 | E11: CM2E PS 轴套分总成 | F11: 100 | G11: =VLOOKUP(D11,'WL CT '!A:C,3,0) | H11: 0 | I11: 1 | J11: 0.03 | K11: 8 | L11: 3 | M11: =3600/G11*C11*K11
A12: WL | B12: 轴套6 | C12: 0.85 | D12: WD48699 | E12: L743 DS轴套分总成 | F12: 100 | G12: =VLOOKUP(D12,'WL CT '!A:C,3,0) | H12: 0 | I12: 1 | J12: 0.03 | K12: 8 | L12: 3 | M12: =3600/G12*C12*K12
A13: WL | B13: 轴套6 | C13: 0.85 | D13: WD48700 | E13: L743 PS轴套分总成 | F13: 100 | G13: =VLOOKUP(D13,'WL CT '!A:C,3,0) | H13: 0 | I13: 1 | J13: 0.03 | K13: 8 | L13: 3 | M13: =3600/G13*C13*K13
... A22: WL | B22: 轴套6 | C22: 0.85 | D22: WCA1927 | E22: KP31 PS 轴套分总成 | F22: 100 | G22: =VLOOKUP(D22,'WL CT '!A:C,3,0) | H22: 0 | I22: 1 | J22: 0.03 | K22: 8 | L22: 3 | M22: =3600/G22*C22*K22
A23: SY38 | B23: 1400T-6 | C23: 0.85 | D23: L755405 | E23: B9RL Fender 2K Outer Lens Left sde | F23: 100 | G23: 100 | H23: 0 | I23: 0.5 | J23: 0 | K23: 12 | L23: 2 | M23: =ROUNDUP(3600/G23*C23*K23,0) | N23: 1 | O23: 1680
A24: SY38 | B24: 1400T-6 | C24: 0.85 | D24: L782264 | E24: B9RL Fender 2K Outer Lens Right sde | F24: 100 | G24: 100 | H24: 0 | I24: 0.5 | J24: 0 | K24: 12 | L24: 2 | M24: =ROUNDUP(3600/G24*C24*K24,0) | N24: 1 | O24: 1680
A25: SY38 | B25: 1400T-6 | C25: 0.85 | D25: L755774 | E25: B9RL Trunk 2K Outer Lens | F25: 100 | G25: 90 | H25: 0 | I25: 0.5 | J25: 0 | K25: 12 | L25: 2 | M25: =ROUNDUP(3600/G25*C25*K25,0) | N25: 1 | O25: 1680
A26: SY38 | B26: 1400T-6 | C26: 0.85 | D26: LAC3180 | E26: BMW G58 箱灯透镜左 | F26: 100 | G26: 60 | H26: 0 | I26: 0.5 | J26: 0 | K26: 12 | L26: 2 | M26: =ROUNDUP(3600/G26*C26*K26,0) | N26: 1 | O26: 400
A27: SY38 | B27: 1400T-6 | C27: 0.85 | D27: LAC3181 | E27: BMW G58 箱灯透镜右 | F27: 100 | G27: 60 | H27: 0 | I27: 0.5 | J27: 0 | K27: 12 | L27: 2 | M27: =ROUNDUP(3600/G27*C27*K27,0) | N27: 1 | O27: 400

Sheet BOM List
A1: Site | B1: SAP总成 | C1: 物料描述 | D1: 半成品号 | E1: 盖板线 | F1: BOM比例
A2: WL | B2: W000014477SKR | C2: GMK T300前雨刮电机传动杆总成 (备件) | D2: W000042905 | E2: 40511 T300司机侧轴套分总成 | F2: 1
A3: WL | B3: W000014477SKR | C3: GMK T300前雨刮电机传动杆总成 (备件) | D3: W000042906 | E3: 40512 T300乘客侧轴套分总成 | F3: 1
A4: WL | B4: W000031992 | C4: Geely FC-1&2 前窗传动杆总成 | D4: W000031998 | E4: Geely FC-1&2 DS轴套分总成 | F4: 1
A5: WL | B5: W000031992 | C5: Geely FC-1&2 前窗传动杆总成 | D5: W000031997 | E5: Geely FC-1&2 PS轴套分总成 | F5: 1
A6: WL | B6: W000031992VA | C6: 吉利 FC-2 前雨刮电机传动杆 | D6: W000031998 | E6: Geely FC-1&2 DS轴套分总成 | F6: 1
A7: WL | B7: W000031992VA | C7: 吉利 FC-2 前雨刮电机传动杆 | D7: W000031997 | E7: Geely FC-1&2 PS轴套分总成 | F7: 1
A8: WL | B8: W000042015AM | C8: 通用爱唯欧前雨刮电机传动杆总成 (独立售后件) | D8: W000042905 | E8: 40511 T300司机侧轴套分总成 | F8: 1
A9: WL | B9: W000042015AM | C9: 通用爱唯欧前雨刮电机传动杆总成 (独立售后件) | D9: W000042906 | E9: 40512 T300乘客侧轴套分总成 | F9: 1
A10: WL | B10: W000045955 | C10: I145B T300 LHD LINKAGE 传动杆组件（KR OES) | D10: W000042906 | E10: 40512 T300乘客侧轴套分总成 | F10: 1
A11: WL | B11: W000045955 | C11: I145B T300 LHD LINKAGE 传动杆组件（KR OES) | D11: W000042905 | E11: 40511 T300司机侧轴套分总成 | F11: 1
A12: WL | B12: W000045956 | C12: I146B T300 LHD LINKAGE传动杆 | D12: W000042905 | E12: 40511 T300司机侧轴套分总成 | F12: 1
A13: WL | B13: W000045956 | C13: I146B T300 LHD LINKAGE传动杆 | D13: W000042906 | E13: 40512 T300乘客侧轴套分总成 | F13: 1
... A66: SY38 | B66: LA96445S | C66: B9RL TRUNK High OEM | D66: L755774 | E66: B9RL Trunk 2K Outer Lens | F66: 1

Sheet Customer Demand
A1: Customer Demand
A2: Site | B2: PN | C2: PN Des | D2: 10/13 | E2: 10/14 | F2: 10/15 | G2: 10/16 | H2: 10/17 | I2: 10/18 | J2: 10/19 | K2: 10/20 | L2: 10/21 | M2: 10/22
A3: WL | B3: WA14208 | C3: DX11电机连杆总成 | D3: 0 | E3: 0 | F3: 0 | G3: 0 | H3: 0 | J3: 0 | K3: 0 | L3: 0 | M3: 0
A4: WL | B4: WAB6404 | C4: E371 A1 传动杆总成 | D4: 0 | E4: 0 | F4: 0 | G4: 0 | H4: 0 | J4: 0 | K4: 0 | L4: 122 | M4: 0
A5: WL | B5: WB35356 | C5: 930B传动杆总成 | D5: 0 | E5: 0 | F5: 1500 | G5: 0 | H5: 0 | J5: 0 | K5: 6720 | L5: 0 | M5: 0
A6: WL | B6: WB80510 | C6: CX11 LHD传动杆总成（新） | D6: 0 | E6: 144 | F6: 0 | G6: 144 | H6: 0 | J6: 144 | K6: 0 | L6: 0 | M6: 0
A7: WL | B7: WC07674 | C7: CM2E 电机及连杆机构 | D7: 0 | E7: 0 | F7: 0 | G7: 0 | H7: 0 | J7: 0 | K7: 0 | L7: 0 | M7: 0
A8: WL | B8: WD48696 | C8: L743 传动杆总成 | D8: 0 | E8: 0 | F8: 0 | G8: 0 | H8: 0 | J8: 180 | K8: 0 | L8: 0 | M8: 360
A9: WL | B9: WD59238 | C9: E371传动杆总成 | D9: 0 | E9: 0 | F9: 0 | G9: 0 | H9: 0 | J9: 192 | K9: 0 | L9: 0 | M9: 0
A10: WL | B10: W144813S | C10: Geely DCY11前雨刮电机传动杆总成 (备件) | D10: 0 | E10: 0 | F10: 0 | G10: 0 | H10: 0 | J10: 0 | K10: 0 | L10: 0 | M10: 0
A11: WL | B11: W000076959VA | C11: 领克 01&03 前雨刮电机传动杆 | D11: 0 | E11: 0 | F11: 0 | G11: 0 | H11: 0 | J11: 0 | K11: 0 | L11: 0 | M11: 0
A12: WL | B12: W243255S | C12: 宝马欧洲G38前雨刮电机传动杆成品 (备件) | D12: 0 | E12: 0 | F12: 0 | G12: 0 | H12: 0 | J12: 0 | K12: 0 | L12: 0 | M12: 0
A13: WL | B13: WA14208S | C13: 吉利DX11左驾前雨刮电机传动杆 (备件) | D13: 0 | E13: 0 | F13: 0 | G13: 0 | H13: 0 | J13: 0 | K13: 0 | L13: 0 | M13: 0
A14: WL | B14: WD48696S | C14: 领克L743左驾前雨刮电机传动杆总成 (备件) | D14: 0 | E14: 0 | F14: 0 | G14: 0 | H14: 0 | J14: 0 | K14: 0 | L14: 0 | M14: 0
... A19: WL | B19: WCA1894 | C19: Chery KP31 LHD 传动杆 | D19: 0 | E19: 0 | F19: 0 | G19: 0 | H19: 180 | J19: 0 | K19: 0 | L19: 0 | M19: 0
A20: SY38 | B20: L755390S | C20: B9 Low Fender L | D20: 0 | E20: 0 | F20: 0 | G20: 140 | H20: 490 | I20: 0 | J20: 420 | K20: 0 | L20: 0 | M20: 210
A21: SY38 | B21: L755392S | C21: B9 Low Fender R | D21: 0 | E21: 0 | F21: 0 | G21: 140 | H21: 490 | I21: 0 | J21: 420 | K21: 0 | L21: 0 | M21: 210
A22: SY38 | B22: LA96403S | C22: B9RL Fender lamp Left side OEM | D22: 0 | E22: 0 | F22: 0 | G22: 0 | H22: 0 | I22: 0 | J22: 0 | K22: 0 | L22: 0 | M22: 0
A23: SY38 | B23: LA96404S | C23: B9RL Fender lamp Right side OEM | D23: 0 | E23: 0 | F23: 0 | G23: 0 | H23: 0 | I23: 0 | J23: 0 | K23: 0 | L23: 0 | M23: 0
A24: SY38 | B24: LA83453S | C24: B9 Low Trunk | D24: 0 | E24: 0 | F24: 0 | G24: 0 | H24: 0 | I24: 0 | J24: 0 | K24: 0 | L24: 0 | M24: 0
A25: SY38 | B25: L755548S | C25: B9 High Trunk | D25: 0 | E25: 0 | F25: 0 | G25: 120 | H25: 504 | I25: 0 | J25: 384 | K25: 0 | L25: 0 | M25: 240
A26: SY38 | B26: LA96445S | C26: B9RL TRUNK High OEM | D26: 0 | E26: 0 | F26: 0 | G26: 0 | H26: 0 | I26: 0 | J26: 0 | K26: 0 | L26: 0 | M26: 0
A27: SY38 | B27: LCC4666ZO04 | C27: BMW NA8 翼灯总成左 | D27: 0 | E27: 0 | F27: 0 | G27: 0 | H27: 0 | I27: 0 | J27: 0 | K27: 0 | L27: 0 | M27: 150
A28: SY38 | B28: LCC4690ZO04 | C28: BMW NA8 翼灯总成右 | D28: 0 | E28: 0 | F28: 0 | G28: 0 | H28: 0 | I28: 0 | J28: 0 | K28: 0 | L28: 0 | M28: 150
A29: SY38 | B29: LCC4710ZN04 | C29: BMW NA8 箱灯总成左 | D29: 0 | E29: 0 | F29: 0 | G29: 0 | H29: 0 | I29: 0 | J29: 0 | K29: 0 | L29: 0 | M29: 150
A30: SY38 | B30: LCC4725ZN04 | C30: BMW NA8 箱灯总成右 | D30: 0 | E30: 0 | F30: 0 | G30: 0 | H30: 0 | I30: 0 | J30: 0 | K30: 0 | L30: 0 | M30: 150

Sheet Initial Stock
A1: Site | B1: Material Type | C1: PN | D1: PN Des | E1: Initial Stock(10/13)
A2: WL | B2: FING | C2: WA14208 | D2: DX11电机连杆总成 | E2: 0
A3: WL | B3: FING | C3: WAB6404 | D3: E371 A1 传动杆总成 | E3: 838
A4: WL | B4: FING | C4: WB35356 | D4: 930B传动杆总成 | E4: 1860
A5: WL | B5: FING | C5: WB80510 | D5: CX11 LHD传动杆总成（新） | E5: 528
A6: WL | B6: FING | C6: WC07674 | D6: CM2E 电机及连杆机构 | E6: 360
A7: WL | B7: FING | C7: WD48696 | D7: L743 传动杆总成 | E7: 1152
A8: WL | B8: FING | C8: WD59238 | D8: E371传动杆总成 | E8: 1024
A9: WL | B9: FING | C9: W144813S | D9: Geely DCY11前雨刮电机传动杆总成 (备件) | E9: 0
A10: WL | B10: FING | C10: W000076959VA | D10: 领克 01&03 前雨刮电机传动杆 | E10: 0
A11: WL | B11: FING | C11: W243255S | D11: 宝马欧洲G38前雨刮电机传动杆成品 (备件) | E11: 0
A12: WL | B12: FING | C12: WA14208S | D12: 吉利DX11左驾前雨刮电机传动杆 (备件) | E12: 0
A13: WL | B13: FING | C13: WD48696S | D13: 领克L743左驾前雨刮电机传动杆总成 (备件) | E13: 0
... A52: WL | B52: SFIN | C52: WD59260 | D52: E371 PS Pivot Assy | E52: 97

Sheet Production plan-Done
C1: 规格信息 | J1: 46307 | N1: 46308 | R1: 46309 | V1: 46310 | Z1: 46311 | AD1: 46312 | AH1: 46313 | AL1: 46314 | AP1: 46315 | AT1: 46316 | AX1: 46317 | BB1: 46318 | BF1: 46319 | BJ1: 46320
A2: 资源代码 | B2: 品目描述 | C2: 成品料号 | D2: 制造时间 | E2: CT | F2: TRP | G2: 制造开始时间 | H2: 备注 | I2: 合计 | J2: 早班 | K2: 中班 | L2: 晚班 | M2: 试产 | N2: 早班 | O2: 中班 | P2: 晚班 | Q2: 试产 | R2: 早班 | S2: 中班 | T2: 晚班 | U2: 试产 | V2: 早班 | W2: 中班 | X2: 晚班 | Y2: 试产 | Z2: 早班 | AA2: 中班 | AB2: 晚班 | AC2: 试产 | AD2: 早班 | AE2: 中班 | AF2: 晚班 | AG2: 试产 | AH2: 早班 | AI2: 中班 | AJ2: 晚班 | AK2: 试产 | AL2: 早班 | AM2: 中班 | AN2: 晚班 | AO2: 试产 | AP2: 早班 | AQ2: 中班 | AR2: 晚班 | AS2: 试产 | AT2: 早班 | AU2: 中班 | AV2: 晚班 | AW2: 试产 | AX2: 早班 | AY2: 中班 | AZ2: 晚班 | BA2: 试产 | BB2: 早班 | BC2: 中班 | BD2: 晚班 | BE2: 试产 | BF2: 早班 | BG2: 中班 | BH2: 晚班 | BI2: 试产 | BJ2: 早班 | BK2: 中班 | BL2: 晚班 | BM2: 试产
A3: 轴套6 | B3: LEAP CU1207&CU1307 DS 轴套分总成 | C3: WBC9318 | D3: 4.4H | E3: 27 | F3: 0.85 | G3: 46307.292 | H3: ORD_WL_WBC9317C_1013 | I3: 494 | J3: 494
A4: 轴套6 | B4: LEAP CU1207&CU1307 PS 轴套分总成 | C4: WBC9324 | D4: 0.9H | E4: 27 | F4: 0.85 | G4: 46307.473 | H4: ORD_WL_WBC9317C_1013 | I4: 100 | J4: 100
A5: 轴套6 | B5: KP31 PS 轴套分总成 | C5: WCA1927 | D5: 4.8H | E5: 27 | F5: 0.85 | G5: 46307.51 | H5: ORD_WL_WCB8574_1017 | I5: 546 | J5: 312 | K5: 234
A6: 轴套6 | B6: LEAP CU1207&CU1307 DS 轴套分总成 | C6: WBC9318 | D6: 10.6H | E6: 27 | F6: 0.85 | G6: 46307.711 | H6: ORD_WL_WBC9317_1020 | I6: 1200 | K6: 125 | L6: 420 | N6: 655
A7: 轴套6 | B7: KP31 DS 轴套分总成 | C7: WCA1903 | D7: 4.8H | E7: 27 | F7: 0.85 | G7: 46307.757 | H7: ORD_WL_WCB8574_1017 | I7: 547 | K7: 547
A8: 轴套6 | B8: LEAP CU1207&CU1307 PS 轴套分总成 | C8: WBC9324 | D8: 10.6H | E8: 27 | F8: 0.85 | G8: 46308.113 | H8: ORD_WL_WBC9317_1020 | I8: 1200 | L8: 486 | N8: 151 | O8: 117 | P8: 100 | R8: 346
A9: 轴套6 | B9: LEAP CU1207&CU1307 DS 轴套分总成 | C9: WBC9318 | D9: 10.6H | E9: 27 | F9: 0.85 | G9: 46308.588 | H9: ORD_WL_WBC9317_1022 | I9: 1200 | N9: 100 | O9: 508 | P9: 592
A10: 轴套6 | B10: 930B PS 轴套分总成 | C10: WC52036 | D10: 58.6H | E10: 29 | F10: 0.85 | G10: 46308.855 | H10: ORD_WL_WB35356_1020 | I10: 6184 | O10: 262 | P10: 100 | R10: 100 | S10: 207 | T10: 201 | V10: 125 | W10: 100 | X10: 529 | Z10: 187 | AA10: 494 | AB10: 443 | AD10: 528 | AE10: 227 | AF10: 481 | AH10: 100 | AI10: 429 | AJ10: 411 | AL10: 420 | AM10: 420 | AN10: 420
A11: 轴套6 | B11: LEAP CU1207&CU1307 PS 轴套分总成 | C11: WBC9324 | D11: 8.7H | E11: 27 | F11: 0.85 | G11: 46309.252 | H11: ORD_WL_WBC9317C_1019 | I11: 990 | P11: 107 | R11: 332 | S11: 551
A12: 轴套6 | B12: 930B DS 轴套分总成 | C12: WC84833 | D12: 58.5H | E12: 29 | F12: 0.85 | G12: 46309.58 | H12: ORD_WL_WB35356_1020 | I12: 6174 | R12: 100 | S12: 124 | T12: 643 | V12: 113 | W12: 101 | X12: 222 | Z12: 657 | AA12: 350 | AB12: 401 | AD12: 316 | AE12: 348 | AF12: 363 | AH12: 341 | AI12: 415 | AJ12: 433 | AL12: 424 | AM12: 403 | AN12: 420
A13: 轴套6 | B13: LEAP CU1207&CU1307 DS 轴套分总成 | C13: WBC9318 | D13: 8.9H | E13: 27 | F13: 0.85 | G13: 46310.386 | H13: ORD_WL_WBC9317C_1019 | I13: 1008 | V13: 219 | W13: 689 | X13: 100
A14: 轴套6 | B14: LEAP CU1207&CU1307 DS 轴套分总成 | C14: WBC9318 | D14: 3.8H | E14: 27 | F14: 0.85 | G14: 46310.466 | H14: ORD_WL_WBC9317C_1022 | I14: 432 | V14: 432
A15: 轴套6 | B15: LEAP CU1207&CU1307 PS 轴套分总成 | C15: WBC9324 | D15: 10.6H | E15: 27 | F15: 0.85 | G15: 46312.852 | H15: ORD_WL_WBC9317_1022 | I15: 1200 | AE15: 288 | AP15: 400 | AQ15: 512
A16: 轴套6 | B16: LEAP CU1207&CU1307 PS 轴套分总成 | C16: WBC9324 | D16: 3.8H | E16: 27 | F16: 0.85 | G16: 46313.466 | H16: ORD_WL_WBC9317C_1022 | I16: 432 | AH16: 432
A17: 轴套6 | B17: LEAP CU1207&CU1307 DS 轴套分总成 | C17: WBC9318 | D17: 7.6H | E17: 27 | F17: 0.85 | G17: 46315.439 | H17: ORD_WL_WBC9317C_1021 | I17: 864 | AP17: 174 | AQ17: 294 | AR17: 396
A18: 轴套6 | B18: LEAP CU1207&CU1307 PS 轴套分总成 | C18: WBC9324 | D18: 7.6H | E18: 27 | F18: 0.85 | G18: 46315.503 | H18: ORD_WL_WBC9317C_1021 | I18: 864 | AP18: 332 | AQ18: 100 | AR18: 432
A19: 轴套6 | B19: 产量汇总 | I19: 23435 | J19: 906 | K19: 906 | L19: 906 | N19: 906 | O19: 887 | P19: 899 | R19: 878 | S19: 882 | T19: 844 | V19: 889 | W19: 890 | X19: 851 | Z19: 844 | AA19: 844 | AB19: 844 | AD19: 844 | AE19: 863 | AF19: 844 | AH19: 873 | AI19: 844 | AJ19: 844 | AL19: 844 | AM19: 823 | AN19: 840 | AP19: 906 | AQ19: 906 | AR19: 828
A20: 轴套6 | B20: 制造工时汇总(h) | D20: 214.9H | I20: 214.86 | J20: 7.99 | K20: 7.99 | L20: 7.99 | N20: 7.99 | O20: 8 | P20: 8 | R20: 7.88 | S20: 8 | T20: 8 | V20: 8 | W20: 7.98 | X20: 8 | Z20: 8 | AA20: 8 | AB20: 8 | AD20: 8 | AE20: 7.99 | AF20: 8 | AH20: 7.99 | AI20: 8 | AJ20: 8 | AL20: 8 | AM20: 7.8 | AN20: 7.96 | AP20: 7.99 | AQ20: 7.99 | AR20: 7.31
A21: 轴套6 | B21: 班次利用率(%) | I21: 99.5 | J21: 99.9 | K21: 99.9 | L21: 99.9 | N21: 99.9 | O21: 100 | P21: 100 | R21: 98.5 | S21: 100 | T21: 100 | V21: 100 | W21: 99.8 | X21: 100 | Z21: 100 | AA21: 100 | AB21: 100 | AD21: 100 | AE21: 99.9 | AF21: 100 | AH21: 99.9 | AI21: 100 | AJ21: 100 | AL21: 100 | AM21: 97.5 | AN21: 99.5 | AP21: 99.9 | AQ21: 99.9 | AR21: 91.3
A22: PGLINKAGE | B22: LEAP CU1207&1307 传动杆总成-三厂 | C22: WBC9317C | D22: 12.6H | E22: 32 | F22: 0.71 | G22: 46307.625 | H22: ORD_WL_WBC9317C_1013 | I22: 1008 | K22: 360 | L22: 360 | N22: 288
A23: PGLINKAGE | B23: Chery KP31 LHD 传动杆 | C23: WCA1894 | D23: 2.2H | E23: 46 | F23: 0.71 | G23: 46307.813 | H23: ORD_WL_WCA1894_1017 | I23: 120 | K23: 120
A24: PGLINKAGE | B24: Chery KP31 RHD 传动杆 | C24: WCB8574 | D24: 11.9H | E24: 46 | F24: 0.71 | G24: 46307.903 | H24: ORD_WL_WCB8574_1017 | I24: 660 | K24: 60 | L24: 180 | N24: 180 | O24: 240
A25: PGLINKAGE | B25: LEAP CU1207&1307 传动杆总成 | C25: WBC9317 | D25: 21.6H | E25: 46 | F25: 0.71 | G25: 46308.577 | H25: ORD_WL_WBC9317_1020 | I25: 1200 | N25: 48 | O25: 192 | P25: 432 | T25: 384 | V25: 144
A26: PGLINKAGE | B26: 930B传动杆总成 | C26: WB35356 | D26: 107.0H | E26: 43 | F26: 0.71 | G26: 46310.246 | H26: ORD_WL_WB35356_1020 | I26: 6360 | T26: 60 | V26: 300 | W26: 360 | X26: 300 | Z26: 420 | AA26: 360 | AB26: 420 | AD26: 420 | AE26: 420 | AF26: 360 | AH26: 420 | AI26: 420 | AJ26: 420 | AL26: 420 | AM26: 420 | AN26: 420 | AP26: 420
A27: PGLINKAGE | B27: LEAP CU1207&1307 传动杆总成-三厂 | C27: WBC9317C | D27: 12.6H | E27: 32 | F27: 0.71 | G27: 46310.877 | H27: ORD_WL_WBC9317C_1019 | I27: 1008 | W27: 144 | X27: 216 | Z27: 72 | AA27: 144 | AB27: 72 | AD27: 72 | AE27: 72 | AF27: 144 | AH27: 72
A28: PGLINKAGE | B28: LEAP CU1207&1307 传动杆总成-三厂 | C28: WBC9317C | D28: 5.4H | E28: 32 | F28: 0.71 | G28: 46313.919 | H28: ORD_WL_WBC9317C_1022 | I28: 432 | AI28: 72 | AJ28: 72 | AL28: 72 | AM28: 72 | AN28: 72 | AP28: 72
A29: PGLINKAGE | B29: LEAP CU1207&1307 传动杆总成 | C29: WBC9317 | D29: 21.6H | E29: 46 | F29: 0.71 | G29: 46315.625 | H29: ORD_WL_WBC9317_1022 | I29: 1200 | AQ29: 432 | AR29: 144 | AT29: 144 | AU29: 432 | AV29: 48
A30: PGLINKAGE | B30: LEAP CU1207&1307 传动杆总成-三厂 | C30: WBC9317C | D30: 10.8H | E30: 32 | F30: 0.71 | G30: 46316.066 | H30: ORD_WL_WBC9317C_1021 | I30: 864 | AR30: 432 | AT30: 432
A31: PGLINKAGE | B31: 产量汇总 | I31: 12852 | K31: 540 | L31: 540 | N31: 516 | O31: 432 | P31: 432 | T31: 444 | V31: 444 | W31: 504 | X31: 516 | Z31: 492 | AA31: 504 | AB31: 492 | AD31: 492 | AE31: 492 | AF31: 504 | AH31: 492 | AI31: 492 | AJ31: 492 | AL31: 492 | AM31: 492 | AN31: 492 | AP31: 492 | AQ31: 432 | AR31: 576 | AT31: 576 | AU31: 432 | AV31: 48
A32: PGLINKAGE | B32: 制造工时汇总(h) | D32: 205.7H | I32: 205.69 | K32: 7.75 | L32: 7.75 | N32: 7.71 | O32: 7.77 | P32: 7.77 | T32: 7.92 | V32: 7.64 | W32: 7.86 | X32: 7.75 | Z32: 7.97 | AA32: 7.86 | AB32: 7.97 | AD32: 7.97 | AE32: 7.97 | AF32: 7.86 | AH32: 7.97 | AI32: 7.97 | AJ32: 7.97 | AL32: 7.97 | AM32: 7.97 | AN32: 7.97 | AP32: 7.97 | AQ32: 7.77 | AR32: 8 | AT32: 8 | AU32: 7.77 | AV32: 0.86
A33: PGLINKAGE | B33: 班次利用率(%) | I33: 95.2 | K33: 96.8 | L33: 96.8 | N33: 96.4 | O33: 97.2 | P33: 97.2 | T33: 99 | V33: 95.5 | W33: 98.2 | X33: 96.9 | Z33: 99.6 | AA33: 98.2 | AB33: 99.6 | AD33: 99.6 | AE33: 99.6 | AF33: 98.2 | AH33: 99.6 | AI33: 99.6 | AJ33: 99.6 | AL33: 99.6 | AM33: 99.6 | AN33: 99.6 | AP33: 99.6 | AQ33: 97.2 | AR33: 100 | AT33: 100 | AU33: 97.2 | AV33: 10.8
A34: 全厂 | B34: 总计(数量) | D34: 420.5H | I34: 36287 | J34: 906 | K34: 1446 | L34: 1446 | N34: 1422 | O34: 1319 | P34: 1331 | R34: 878 | S34: 882 | T34: 1288 | V34: 1333 | W34: 1394 | X34: 1367 | Z34: 1336 | AA34: 1348 | AB34: 1336 | AD34: 1336 | AE34: 1355 | AF34: 1348 | AH34: 1365 | AI34: 1336 | AJ34: 1336 | AL34: 1336 | AM34: 1315 | AN34: 1332 | AP34: 1398 | AQ34: 1338 | AR34: 1404 | AT34: 576 | AU34: 432 | AV34: 48

Sheet SZ Sample
A1: 基本信息 | D1: 规格信息 | O1: 46307 | S1: 46308 | W1: 46309 | AA1: 46310 | AE1: 46311 | AI1: 46312
A2: 资源描述 | B2: 资源代码 | C2: 品目描述 | D2: 成品料号 | E2: 产品族 | F2: 工单号 | G2: 制造时间 | H2: CT | I2: TRP | J2: TRP2 | K2: PCBA | L2: 制造开始时间 | M2: 备注 | N2: 合计 | O2: 早班 | P2: 中班 | Q2: 晚班 | R2: 试产 | S2: 早班 | T2: 中班 | U2: 晚班 | V2: 试产 | W2: 早班 | X2: 中班 | Y2: 晚班 | Z2: 试产 | AA2: 早班 | AB2: 中班 | AC2: 晚班 | AD2: 试产 | AE2: 早班 | AF2: 中班 | AG2: 晚班 | AH2: 试产 | AI2: 早班 | AJ2: 中班 | AK2: 晚班 | AL2: 试产
A3: 资源代码: WC23ECU1
B4: WC23ECU1 | D4: ECF3708 | F4: PT-0007 | G4: 2.0H | I4: 0.92 | J4: 1 | L4: 46307.292 | N4: 20 | R4: 20
B5: WC23ECU1 | C5: 12CH ECU with SW D5.13 deliver to DPCA | D5: E500379-01 | E5: 308894 | F5: PT-0004 | G5: 1.0H | H5: 24 | I5: 0.92 | J5: 1 | K5: 308894 | L5: 46307.375 | N5: 145 | O5: 145
B6: WC23ECU1 | C6: L21B 24MY TWN HL ECU ASSY | D6: EB09585-00 | E6: E127512 | F6: PT-0005 | G6: 0.8H | H6: 21 | I6: 0.92 | J6: 1 | K6: E127512 | L6: 46307.426 | N6: 140 | O6: 140
B7: WC23ECU1 | C7: ECU ASSY YHB(MSIL) NORMAL_4CH | D7: 312436 | E7: 312061 | F7: PT-0006 | G7: 17.2H | H7: 23 | I7: 0.92 | J7: 1 | K7: 312061 | L7: 46307.47 | N7: 2688 | O7: 1207.8261 | Q7: 1480.1739
B8: WC23ECU1 | C8: ECU ASSY YHB(MSIL) NORMAL_4CH | D8: 312436 | E8: 312061 | F8: PT-0010 | G8: 2.5H | H8: 23 | I8: 0.92 | J8: 1 | K8: 312061 | L8: 46308.292 | N8: 384 | S8: 384
B9: WC23ECU1 | C9: ECU ASSY YHC (MSIL) _ 4CH | D9: B200089 | E9: 312061 | F9: PT-0011 | G9: 10.5H | H9: 24.5 | I9: 0.92 | J9: 1 | K9: 312061 | L9: 46308.404 | N9: 1536 | S9: 1366.0408 | U9: 169.95918
B10: WC23ECU1 | C10: ECU ASSY Y9T(MSIL 4CH) with AK sensor | D10: EBB4746 | E10: 312061 | F10: PT-0013 | G10: 8.3H | H10: 26 | I10: 0.92 | J10: 1 | K10: 312061 | L10: 46308.85 | N10: 1152 | U10: 1152
B11: WC23ECU1 | C11: 4ch ECU | D11: ED49216-00 | E11: EA98181 | F11: MO-2-TASK | G11: 0.5H | H11: 23 | I11: 0.92 | J11: 1 | K11: EA98181 | L11: 46309.207 | N11: 72 | U11: 72
B12: WC23ECU1 | C12: ECU ASSY Y9T(MSIL 4CH) with AK sensor | D12: EBB4746 | E12: 312061 | F12: PT-0014 | G12: 2.8H | H12: 26 | I12: 0.92 | J12: 1 | K12: 312061 | L12: 46309.292 | N12: 384 | W12: 384
B13: WC23ECU1 | C13: ECU ASSY YHB(MSIL) NORMAL_4CH | D13: 312436 | E13: 312061 | F13: PT-0015 | G13: 19.0H | H13: 23 | I13: 0.92 | J13: 1 | K13: 312061 | L13: 46309.418 | N13: 2976 | W13: 1405.0435 | Y13: 1570.9565
B14: WC23ECU1 | C14: ECU ASSY YHB(MSIL) NORMAL_4CH | D14: 312436 | E14: 312061 | F14: PT-0017 | G14: 10.4H | H14: 23 | I14: 0.92 | J14: 1 | K14: 312061 | L14: 46310.292 | N14: 1632 | AA14: 1632
B15: WC23ECU1 | C15: 4ch ECU | D15: ED49216-00 | E15: EA98181 | F15: PT-0018 | G15: 6.4H | H15: 23 | I15: 0.92 | J15: 1 | K15: EA98181 | L15: 46310.737 | N15: 1008 | AA15: 207.13044 | AC15: 800.86956
B16: WC23ECU1 | C16: 4ch ECU | D16: ED49216-00 | E16: EA98181 | F16: PT-0020 | G16: 21.2H | H16: 23 | I16: 0.92 | J16: 1 | K16: EA98181 | L16: 46311.292 | N16: 3312 | AE16: 1878.2609 | AG16: 1433.7391
B17: WC23ECU1 | C17: 4ch ECU | D17: ED49216-00 | E17: EA98181 | F17: PT-0022 | G17: 21.2H | H17: 23 | I17: 0.92 | J17: 1 | K17: EA98181 | L17: 46312.292 | N17: 3312 | AI17: 1878.2609 | AK17: 1433.7391
H19: 305.5 | N19: 18761 | O19: 1492.8261 | Q19: 1480.1739 | R19: 20 | S19: 1750.0408 | U19: 1393.9592 | W19: 1789.0435 | Y19: 1570.9565 | AA19: 1839.1304 | AC19: 800.86956 | AE19: 1878.2609 | AG19: 1433.7391 | AI19: 1878.2609 | AK19: 1433.7391
A20: 资源代码: WC23ECU2
B21: WC23ECU2 | C21: L42P UPA ECU ASSY | D21: 314102-01 | E21: 307823 | F21: PT-0024 | G21: 0.3H | H21: 24 | I21: 0.8 | J21: 1 | K21: 307823 | L21: 46307.292 | N21: 40 | O21: 40
B22: WC23ECU2 | C22: P42M 8K UPA ECU Assy | D22: 308674 | E22: 307823 | F22: PT-0025 | G22: 0.4H | H22: 21.5 | I22: 0.8 | J22: 1 | K22: 307823 | L22: 46307.317 | N22: 66 | O22: 66
B23: WC23ECU2 | C23: Nissan P02F UPA ECU Assy 3K | D23: 310847-00 | E23: 307823 | F23: PT-0026 | G23: 0.8H | H23: 20.4 | I23: 0.8 | J23: 1 | K23: 307823 | L23: 46307.347 | N23: 144 | O23: 144
B24: WC23ECU2 | C24: H60A LL ECU Assy. NCIC | D24: E301830-00 | E24: 307823 | F24: PT-0027 | G24: 0.2H | H24: 21 | I24: 0.8 | J24: 1 | K24: 307823 | L24: 46307.395 | N24: 40 | O24: 40
B25: WC23ECU2 | C25: L42P EAP ECU ASSY | D25: E582125-01 | E25: 308136 | F25: PT-0028 | G25: 0.5H | H25: 18 | I25: 0.8 | J25: 1 | K25: 308136 | L25: 46307.425 | N25: 100 | O25: 100
B26: WC23ECU2 | C26: Nissan C53D 8CH EAP ECU unit, Low line | D26: EC09431 | E26: 308136 | F26: PT-0029 | G26: 1.4H | H26: 26 | I26: 0.8 | J26: 1 | K26: 308136 | L26: 46307.46 | N26: 192 | O26: 192
B27: WC23ECU2 | C27: XC2A 24MY CONT ASSY-SONAR STD | D27: EF40137 | E27: E876082 | F27: PT-0030 | G27: 6.2H | H27: 26 | I27: 0.8 | J27: 1 | K27: E876082 | L27: 46307.539 | N27: 864 | O27: 840.42308 | Q27: 23.576923
B28: WC23ECU2 | C28: XC2A 24MY CONT ASSY-SONAR HWS | D28: EF40165 | E28: E876082 | F28: PT-0032 | G28: 3.1H | H28: 26 | I28: 0.8 | J28: 1 | K28: E876082 | L28: 46307.813 | N28: 432 | Q28: 432
B29: WC23ECU2 | C29: LOW-LINE SONAR ECU ASSY R500 RC4 | D29: EAA2003 | E29: E876082 | F29: PT-0033 | G29: 2.6H | H29: 26 | I29: 0.8 | J29: 1 | K29: E876082 | L29: 46307.957 | N29: 360 | Q29: 360
B30: WC23ECU2 | C30: LOW-LINE SONAR ECU ASSY R500 RC4 | D30: EAA2041 | E30: E876082 | F30: PT-0034 | G30: 0.3H | H30: 26 | I30: 0.8 | J30: 1 | K30: E876082 | L30: 46308.079 | N30: 36 | Q30: 36
B31: WC23ECU2 | C31: X81C 25MC Assy L1W1 | D31: EE74059 | E31: E894715 | F31: PT-0035 | G31: 1.4H | H31: 26 | I31: 0.8 | J31: 1 | K31: E894715 | L31: 46308.111 | N31: 192 | Q31: 192
B32: WC23ECU2 | C32: X81C 25MC Assy L2W2 | D32: EE92487 | E32: E894715 | F32: PT-0036 | G32: 0.3H | H32: 26 | I32: 0.8 | J32: 1 | K32: E894715 | L32: 46308.182 | N32: 48 | Q32: 48
B33: WC23ECU2 | C33: MMC B SUV ECU UNIT, SW R520 | D33: EC74747-00 | E33: E242347 | F33: PT-0037 | G33: 14.6H | H33: 26 | I33: 0.8 | J33: 1 | K33: E242347 | L33: 46308.312 | N33: 2016 | S33: 1592.3077 | U33: 423.69231
B34: WC23ECU2 | C34: 4ch ECU | D34: ED49216-00 | E34: EA98181 | F34: MO-1-TASK | G34: 6.2H | H34: 25 | I34: 0.8 | J34: 1 | K34: EA98181 | L34: 46308.94 | N34: 144 | U34: 144
B35: WC23ECU2 | C35: PSA ECU 12-Ch DC Wave3.23 D5.4 | D35: EBA2629 | E35: E784458 | F35: PT-0039 | G35: 5.2H | H35: 26 | I35: 0.8 | J35: 1 | K35: E784458 | L35: 46308.94 | N35: 720 | U35: 720
B36: WC23ECU2 | C36: PSA ECU 12-Ch DC Wave3.23 D5.4 | D36: EBA2629 | E36: E784458 | F36: PT-0040 | G36: 10.4H | H36: 26 | I36: 0.8 | J36: 1 | K36: E784458 | L36: 46309.292 | N36: 1440 | W36: 1440
B37: WC23ECU2 | D37: ECF8214-00 | F37: PT-0041 | G37: 2.0H | I37: 0.8 | J37: 1 | L37: 46309.725 | N37: 51 | Z37: 51
B38: WC23ECU2 | C38: SWEET400 P61Q Assy R590RS7 | D38: EAB5003 | E38: E242347 | F38: PT-0044 | G38: 5.5H | H38: 26 | I38: 0.8 | J38: 1 | K38: E242347 | L38: 46309.829 | N38: 756 | Y38: 756
B39: WC23ECU2 | C39: NISSAN PZ1A 25MY SWEET 400 ECU ASSY | D39: ECF1217-00 | E39: E242347 | F39: PT-0045 | G39: 0.7H | H39: 26 | I39: 0.8 | J39: 1 | K39: E242347 | L39: 46310.071 | N39: 96 | Y39: 96
B40: WC23ECU2 | C40: 4ch ECU | D40: ED49216-00 | E40: EA98181 | F40: PT-0046 | G40: 10.5H | H40: 25 | I40: 0.8 | J40: 1 | K40: EA98181 | L40: 46310.312 | N40: 1512 | AA40: 1512
B41: WC23ECU2 | C41: 4ch ECU | D41: ED49216-00 | E41: EA98181 | F41: PT-0047 | G41: 4.5H | H41: 25 | I41: 0.8 | J41: 1 | K41: EA98181 | L41: 46311.292 | N41: 648 | AE41: 648
...

Sheet 排产原则-约束条件
A1: Site | B1: Material Type | C1: 排产逻辑 | D1: 约束条件 | E1: 权重（%） | F1: AI排产逻辑规范化解析与示例 (AI Logic & Example)
A2: WE34 | B2: SFIN | C2: 第一优先级班次产能利用率要大于95% | D2: 硬约束 | F2: 【逻辑公式】开工负荷硬约束（优先级P1）：Utilization(Shift) = 实际产量 / 班次额定产能 ≥ 95.0%。 【业务边界】工位/机台开线即要求高度饱满，不足95%负荷禁止开工。 【场景示例】SFIN工序单班标称产能1000件。若需求仅能凑出700件(70%)，系统禁止强行开工，强制合并批次或跨班挪移，确保单班计划≥950件。
A3: WE34 | B3: SFIN | C3: 第二优先级是保证上级成品线不断线 | D3: 硬约束 | F3: 【逻辑公式】后道防断线硬约束（优先级P2）：SFIN_Stock(t) ≥ FG_Assembly_Demand(t)，断线惩罚 M = ∞。 【业务边界】半成品库存必须时刻覆盖成品装配拉动，供应短缺触发最高级报警。 【场景示例】成品总装计划周三14:00上线300套，SFIN工序在周三14:00前入库累计必须≥300套，否则前道工单强制插至最前置排产。
A4: WE34 | B4: SFIN | C4: 累计排产匹配总需求，停止下达后续生产计划 | D4: 硬约束 | F4: 【逻辑公式】完工锁盘硬约束（优先级P3）：若 ∑_{1..t} Output ≥ Total_Order_Qty，则后续排产立即终止。 【业务边界】严格按单制造，无额外余量排产，累计达标后封锁计划下发。 【场景示例】月度合同需求5000件，当第22天累计排产达到5000件时，系统锁定该产品，后续8天排产自动置为0。
A5: WE34 | B5: SFIN | C5: 产品排产时间窗口限制（特定产品只能安排在特定时间段生产(类似项目首批生产跟线)） | D5: 硬约束 | F5: 【逻辑公式】工艺窗口硬约束（优先级P4）：Job_Time_Window ⊆ [Window_Start, Window_End]。 【业务边界】特殊产品（工程打样、首批量产、专家跟线）只能在指定受控时段生产。 【场景示例】新品首批爬坡件限定周三09:00-12:00生产（工艺工程师跟线）。算法禁止排入夜班或周末，严格锁定此专用窗口。
A6: WE34 | B6: SFIN | C6: 第三级是需要按照设定的工厂日历生产(当需求少于设定的工作日历,优先考虑周六周日放假) | D6: 软约束 | E6: 0.4 | F6: 【逻辑公式】标准日历优先级软约束（权重40%）：若 总需求 ≤ 工作日产能，则 周末生产工时 = 0。 【业务边界】需求量未超常规工时负荷时，优先周六周日全线停机放假。 【场景示例】全周需求4000件，周一至周五标准产能为4500件。优化器优先排在周一至周五，周六周日排休，避免产生不必要的加班成本。
A7: WE34 | B7: SFIN | C7: 第四优先级为保证月底库存,不得大于设定的安全库存标准天数 | D7: 软约束 | E7: 0.35 | F7: 【逻辑公式】月末库存压降软约束（权重35%）：Month_End_Stock ≤ Target_Days × 日均需求。 【业务边界】月底严格限制半成品沉淀，控制库存占用标准天数。 【场景示例】安全库存上限为3天用量（300件）。月末排产推演若达420件（超库120件），扣除0.35权重罚分，算法自动减少月末最后两天的投产量。
A8: WE34 | B8: SFIN | C8: 第五优先级为保证按照生产最小批量生产 | D8: 软约束 | E8: 0.25 | F8: 【逻辑公式】经济批量对齐软约束（权重25%）：Batch_Qty = k × MPQ (k ∈ ℕ⁺)。 【业务边界】尽量按照标准整批/整箱投料，减少散数、零头料管理成本。 【场景示例】最小包装量MPQ=500件。需求为650件时，算法权衡凑整为1000件或按650件排产，施加0.25权重约束引导批量规范化。
A9: WE34 | B9: FING | C9: 当天早班生生产计划完成后的库存必须满足当天客户的需求 | D9: 硬约束 | F9: 【逻辑公式】早班交付截单硬约束：Morning_Shift_Output + 初始库存 ≥ 当天客户发货总需求。 【业务边界】成品当日发运以早班生产入库为截止线，早班下班后必须备齐发货量。 【场景示例】客户周四提货500件。早班初存100件，周四早班装配量必须≥400件并完工入库，杜绝依赖中班或晚班追赶当天发运。
A10: WE34 | B10: FING | C10: 最小生产启动批次量要满足MPQ,当班产能小于MPQ,在下一个班连续生产 | D10: 硬约束 | F10: 【逻辑公式】连续跨班不可分割硬约束：Batch ≥ MPQ；若 班次产能 < MPQ，连续排产不可换线。 【业务边界】整批生产不可中途中断，单班做不完强制在下一班连续排满MPQ。 【场景示例】MPQ为1200件，产线单班仅能做800件。系统自动锁定早班800件+中班400件连续作业，中间严禁切换其他产品。
A11: WE34 | B11: FING | C11: 单班排产的产能利用率要达到95% | D11: 硬约束 | F11: 【逻辑公式】成品工序满载硬约束：Shift_Utilization = 排产工时 / 班次定额工时 ≥ 95.0%。 【业务边界】WE34成品装配开线即需达到高效满负荷运行，避免产线低效闲置。 【场景示例】装配线额定单班800件。若排产仅600件(利用率75%)，判定违背硬约束无法下发，系统触发合班或延后批量排产。
A12: WE34 | B12: FING | C12: 累计排产匹配总需求，停止下达后续生产计划 | D12: 硬约束 | F12: 【逻辑公式】成品按单交付硬约束：∑ Output = Total_Demand，严格闭环生产。 【业务边界】杜绝过度推式生产造成成品高库龄积压，匹配总订单即止。 【场景示例】某料号总采购订单2000件。系统精准排满2000件后即刻关停工单，不再排入任何无订单预测的额外数量。
A13: WE34 | B13: FING | C13: 产品排产时间窗口限制（特定产品只能安排在特定时间段生产(类似项目首批生产跟线)） | D13: 硬约束 | F13: 【逻辑公式】特定首批跟线时间窗硬约束：Schedule_Range ⊆ Defined_Time_Slot。 【业务边界】需特殊资源（质检跟线、设备调机）配套的批次，严格限制在指定时间段。 【场景示例】指定某高端总成只能在周二下午13:00-17:00（质保主管在岗）生产，排程引擎在该时段独占产线排产。
A14: WE34 | B14: FING | C14: 第四优先级是需要按照设定的工厂日历生产(当需求满足不了设定的工作日历,优先考虑周六周日放假) | D14: 软约束 | E14: 0.3 | F14: 【逻辑公式】日历节拍排程软约束（权重30%）：Weekend_Working_Penalty = 0.30 × ∑ (周末开工工时)。 【业务边界】当产能满足需求时，算法优先选择周六周日产线静默放假。 【场景示例】全月订单160工时，做五休二刚好平准。系统优先排出标准做五休二日历，周末排休无罚分，保障员工劳动法规遵循。
A15: WE34 | B15: FING | C15: 第五优先级为月底安全库存控制,在月初产能允许的情况下尽控制到不超过两天的安全库存 | D15: 软约束 | E15: 0.2 | F15: 【逻辑公式】月末安全库存管控软约束（权重20%）：Month_End_Stock ≤ 2 × 日均发货需求。 【业务边界】在月初及月中产能充裕时，平准化调节日产量，月末库存严禁超过2天。 【场景示例】日发货量100件，月末安全库存限额200件。系统在月末前夕主动削减高库存物料的日投产，确保月末结存不超200件。
A16: WE34 | B16: FING | C16: 第六优先级成品当天结余库存需要满足客户第二天的发货需求 | D16: 软约束 | E16: 0.1 | F16: 【逻辑公式】次日发货安全缓冲软约束（权重10%）：Closing_Stock(Day N) ≥ Demand(Day N+1)。 【业务边界】当天日终必须留足次日全天发货需求，防范突发缺件与设备故障。 【场景示例】周五出货计划300件。周四晚24:00库存储备若低于300件，扣除10%权重惩罚分，倒逼周四排产前置拉高库存。
A17: WE34 | B17: FING | C17: 第七优先级当未来一个月需求少于1个小时的产量,按照一个小时的量生产 | D17: 软约束 | E17: 0.1 | F17: 【逻辑公式】微量需求经济工时软约束（权重10%）：若 需求量 < 1小时额定产能，则 排产量 = 1小时额定产能。 【业务边界】防止超微小批次频繁换型，对极低频订单实行1小时最小产能规整。 【场景示例】某售后尾单月需求仅10件，但机台时产120件。系统直接下达120件（1小时产能）排产，其余110件入库待后续慢销。
A18: WE34 | B18: FING | C18: 第八优先级单板班次换型次数要小于等于3次 | D18: 软约束 | E18: 0.1 | F18: 【逻辑公式】班次换型频次上限软约束（权重10%）：Changeovers_Per_Shift ≤ 3。 【业务边界】单班最大允许3次模具/工装切换，避免过多换型损耗产线综合稼动率(OEE)。 【场景示例】单班若排入5个小批次（需换型4次），系统扣减10%惩罚分，推动排程算法将相似物料合并或将换型分散至不同班次。
A19: WE34 | B19: 核心排班 | C19: 三阶智能排班-极度空闲（做四休三）：总需求 ≤ 总产能 4/7，优先排周一至周四 | D19: 硬约束 | F19: 【排班规则】阶梯1（极度空闲）：若 Demand_Weekly ≤ 4/7 × Max_Capacity，Work_Days = {周一, 周二, 周三, 周四}，Off_Days = {周五, 周六, 周日}。 【业务边界】低负荷时集中压缩开机天数，降本节能。 【仿真示例】周极限产能7000件。当周总需求仅3500件（≤4000件），系统自动激活“做四休三”日历，周一至周四满负荷生产，周五至周日停工休假。
A20: WE34 | B20: 核心排班 | C20: 三阶智能排班-正常均衡（做五休二）：总需求 ≤ 总产能 5/7，优先排周一至周五 | D20: 硬约束 | F20: 【排班规则】阶梯2（正常均衡）：若 4/7 × Max_Cap < Demand_Weekly ≤ 5/7 × Max_Cap，Work_Days = {周一至周五}，Off_Days = {周六, 周日}。 【业务边界】标准法定工作制，工时平准化排程。 【仿真示例】周极限产能7000件。周需求为4800件（在4000与5000之间），系统激活“做五休二”日历，周一至周五平摊生产960件/天，周六周日产线正常双休。
A21: WE34 | B21: 核心排班 | C21: 三阶智能排班-产能紧张（连续生产）：总需求 > 总产能 5/7，取消休息日，全月或局部连续排产 | D21: 硬约束 | F21: 【排班规则】阶梯3（产能紧张）：若 Demand_Weekly > 5/7 × Max_Cap，Work_Days = {周一至周日}，Work_Calendar = 连续生产/无休。 【业务边界】订单高企时打破常规周末休息，全量释放极限产能。 【仿真示例】周极限产能7000件。周需求达6200件（>5000件），系统触发排班升阶，自动取消周六周日休息，排定7天连续开工以保障准时交付。
A22: WE34 | B22: 需求倒排 | C22: 需求前置（倒排运算）：遇到休息日时，算法必须将休息日的交货需求提前分配到工作日生产，并在休息日前一天生成安全库存 | D22: 硬约束 | F22: 【排班规则】需求倒排推算：若 Day(T) ∈ 休息日 且 Demand(T) > 0，则 Shift_Target(T-k) += Demand(T)，且 Stock(T_Pre_Rest) ≥ ∑_{Rest} Demand。 【业务边界】休息日发货需求逆向回溯，前置在休假前最后一个工作日完工入库。 【仿真示例】工厂周六日双休，客户周六提货200件、周日提货300件。算法将这500件需求前置倒排至周五或更早生产，确保周五晚结存增加500件。
A23: WE34 | B23: 异常应对 | C23: 复杂异常场景应对策略：针对“前两周需求远超极限产能，后两周无订单”的不均衡场景，系统需支持跨周期滚动与动态日历调度 | D23: 业务策略 | F23: 【异常策略】非均衡波峰响应：支持宏观日历跨周期滚动切片与局部日历弹性分裂调度。 【业务边界】应对月初集中爆单、月末断崖式闲置等“前端拥堵”极端场景。 【仿真示例】某月前两周需求10000件（极限产能仅7000件），后两周需求仅1000件。系统不采用全月均摊做五休二，而是前两周启动无休连排+跨月预排+缺口延期组合策略。
A24: WE34 | B24: 异常应对 | C24: 跨周期滚动预排：打破“自然月”限制，当前半月产能溢出时，自动寻找上个月月末的空闲产能提前排产 | D24: 硬约束 | F24: 【异常策略】跨月滚动预排：若 Demand_H1 > Capacity_H1，则 缺口Target 自动向前逆向搜索上一月月末空闲窗口。 【业务边界】打破自然月财务界限，产销协同前置排产消除峰值拥堵。 【仿真示例】4月前半月产能缺口2000件。系统自动检索3月最后一周发现有2500件富余产能，直接将2000件工单提前至3月25-31日生产并作为期初库存结转至4月。
A25: WE34 | B25: 异常应对 | C25: 周/日级颗粒度日历：允许同月内出现“日历分化”。前两周强制执行“无休连续生产”，后两周自动切换为“集中休假/停线” | D25: 硬约束 | F25: 【异常策略】分段日历粒度：Calendar(Line, Period_1) ≠ Calendar(Line, Period_2)，支持同月多套日历组合。 【业务边界】严禁同月一刀切排班，允许前紧后松动态切换。 【仿真示例】同一产线在4月第1-2周绑定“7天×24小时连续生产日历”；进入第3-4周订单骤减，系统自动切换绑定为“做三休四集中轮休日历”。
A26: WE34 | B26: 异常应对 | C26: 交期平移与延期告警：若无论如何加班都无法按期交货，系统需锁定产能缺口，输出《交期调整建议表》，明确建议哪些订单需延期至月末空闲期 | D26: 硬约束 | F26: 【异常策略】产能锁定与延期建议：若 极限产能 + 预排 + 加班 仍无法满足交期，锁定超额订单并生成《交期调整建议表》。 【业务边界】不可抗力交付缺口透明化，算法自动给出最佳延期平移建议日期。 【场景示例】某紧急订单1500件交期为10日，产线全负荷运转至10日仍有500件绝对缺口。系统锁定该500件并出具告警建议：“建议顺延至20日（月末空闲期）交付”。
A27: WE34 | B27: 系统架构 | C27: 产线与日历彻底解耦：“排班模板”必须作为独立主数据。一条产线可动态绑定多套日历（按周/按天生效），严禁在代码中写死“周末不排产” | D27: 架构约束 | F27: 【架构规范】产线-日历解耦：Line_Master 与 Calendar_Template 保持 N:N 弱关联，通过 [Line_ID, Calendar_ID, 生效时段] 动态绑定。 【业务边界】严禁在算法核心硬编码 weekend_off=True；日历作为外部可配置数据驱动。 【架构示例】数据库中创建独立日历库（标准双休、做六休一、四班三倒、停线检修）。算法引擎每次调度根据订单负荷动态调用不同日历ID，不修改底层代码。
A28: WE34 | B28: 测试场景 | C28: 极度空闲测试：验证系统能否正确集中在周一至周四排产，且周四预估库存能覆盖周末需求 | D28: 测试用例 | F28: 【测试验证】极度空闲用例：输入月需求3000件（极限产能10000件）。 【验证准则】①排产日全部落于周一至周四；②周五至周日开机工时为0；③周四24:00库存值精确覆盖周五至周日的所有发货量。 【输出断言】Assert(Days_Worked == Mon_Thu) && Assert(Weekend_Stock_Cover == 100%)。
A29: WE34 | B29: 测试场景 | C29: 局部波峰测试：总体算下来做五休二，但某一周突发激增，系统需能自动将该周临时切换为做六休一或无休 | D29: 测试用例 | F29: 【测试验证】局部脉冲用例：全月总负荷65%（整体做五休二），但第2周突发激增单周负荷130%。 【验证准则】①系统第1、3、4周保持做五休二；②仅将第2周局部升阶为做六休一或连续排产；③突发需求消除后自动回退至做五休二。 【输出断言】Assert(Week2_Calendar == Overtime_7Days) && Assert(Week3_Calendar == Standard_5Days)。
A30: WE34 | B30: 测试场景 | C30: 前端拥堵测试：前半月爆单后半月闲，验证系统绝不会给出“均摊式的做五休二”，而是前半月满载，并正确处理前半月做不完的溢出订单（提早排或延期告警） | D30: 测试用例 | F30: 【测试验证】前端拥堵用例：输入前15天负荷150%，后15天负荷20%。 【验证准则】①禁止在后15天均摊排产导致前半月断货；②前半月拉满7×24H极限产能；③剩余溢出订单向前倒排或精准触发交期延期告警。 【输出断言】Assert(H1_Utilization == 100%) && Assert(Delay_Notice_Generated == True)。
A31: WE34 | B31: 测试场景 | C31: 绝对超载测试：需求 > 连续生产极限产能时，系统必须抛出“产能缺口告警” | D31: 测试用例 | F31: 【测试验证】绝对超载用例：全月订单需求 > 全月30天7×24H极限理论产能。 【验证准则】①算法终止无效寻优；②直接计算绝对产能差额 Gap = Total_Demand - Max_Month_Cap；③精准输出《产能瓶颈告警及委外/扩产建议清单》。 【输出断言】Assert(Status == "CAPACITY_OVERLOAD_EXCEPTION") && Assert(Gap_Qty > 0)。

Sheet WL CT 
A1: Material | B1: Material Number | C1: Machine Time
A2: 181709 | B2: MAN Truck L37 VWS Main bow Sub Assy | C2: 8
A3: 53006756 | B3: SGM 258MCE Gear Wheel Assy | C3: 6.5
A4: 53006896 | B4: FIAT 343 Gear Wheel Assy | C4: 9
A5: 53027004 | B5: MMYY ERAR COVER | C5: 25
A6: 53042296 | B6: FIAT 343 Cover Plate Assy | C6: 18
A7: 53051356 | B7: AMPLIFIER ASSY CHB071 | C7: 18.3
A8: 53052166 | B8: P42K amplifier assy | C8: 18.3
A9: 53270686 | B9: K211 Armature Assy | C9: 16
A10: 53343106 | B10: Brush Plate non electronic Assy 2L 1C(0. | C10: 28
A11: 53370436 | B11: VWS Brush Box Assy | C11: 14
A12: 53569404 | B12: P32L FRONT MNG2 AC MOTOR | C12: 19
A13: 54028436 | B13: P32L RHD PS lever assy | C13: 9
... A18: 54528511 | B18: P32M RHD MOTOR LINKAGE | C18: 34
A19: 14900108S | B19: JD21M NUT | C19: 0
A20: 150475P | B20: Tiguan RAB assy after package | C20: 18
A21: 178645PJ | B21: SUV LHD DS/PS adaptor for Juarez | C21: 1
A22: 180975WL | B22: Bend sub assembly(DPCA | C22: 10
A23: 24029689S | B23: OES SGM T300 Front Arm Nut Cap FG | C23: 1
A24: 24030957PJ | B24: SUV Nut cap for Juarez | C24: 1
A25: 53006756P | B25: SGM 258MCE Gear Wheel Assy packaging | C25: 1
A26: 53006896P | B26: FIAT 343 Gear Wheel Assy packaging | C26: 1
A27: 53010246L | B27: Gearwheel MNG2 ASSY | C27: 14
A28: 53010246LP | B28: 4NB Gearwheel MNG2 ASSY packaging | C28: 1
A29: 53569404M | B29: P32L FRONT MNG2 AC MOTOR | C29: 0
A30: 53860267P | B30: Renault HZH Seal B | C30: 2.5
... A2340: W000042881P | B2340: X11C MOTOR ARMATURE ASSY Packaged | C2340: 0

Sheet Sample
C1: 规格信息 | J1: 46307 | N1: 46308 | R1: 46309 | V1: 46310 | Z1: 46311 | AD1: 46312 | AH1: 46313 | AL1: 46314 | AP1: 46315 | AT1: 46316 | AX1: 46317 | BB1: 46318 | BF1: 46319 | BJ1: 46320 | BN1: 46321 | BR1: 46322 | BV1: 46323 | BZ1: 46324
A2: 资源代码 | B2: 品目描述 | C2: 成品料号 | D2: 制造时间 | E2: CT | F2: TRP | G2: 制造开始时间 | H2: 备注 | I2: 合计 | J2: 早班 | K2: 中班 | L2: 晚班 | M2: 试产 | N2: 早班 | O2: 中班 | P2: 晚班 | Q2: 试产 | R2: 早班 | S2: 中班 | T2: 晚班 | U2: 试产 | V2: 早班 | W2: 中班 | X2: 晚班 | Y2: 试产 | Z2: 早班 | AA2: 中班 | AB2: 晚班 | AC2: 试产 | AD2: 早班 | AE2: 中班 | AF2: 晚班 | AG2: 试产 | AH2: 早班 | AI2: 中班 | AJ2: 晚班 | AK2: 试产 | AL2: 早班 | AM2: 中班 | AN2: 晚班 | AO2: 试产 | AP2: 早班 | AQ2: 中班 | AR2: 晚班 | AS2: 试产 | AT2: 早班 | AU2: 中班 | AV2: 晚班 | AW2: 试产 | AX2: 早班 | AY2: 中班 | AZ2: 晚班 | BA2: 试产 | BB2: 早班 | BC2: 中班 | BD2: 晚班 | BE2: 试产 | BF2: 早班 | BG2: 中班 | BH2: 晚班 | BI2: 试产 | BJ2: 早班 | BK2: 中班 | BL2: 晚班 | BM2: 试产 | BN2: 早班 | BO2: 中班 | BP2: 晚班 | BQ2: 试产 | BR2: 早班 | BS2: 中班 | BT2: 晚班 | BU2: 试产 | BV2: 早班 | BW2: 中班 | BX2: 晚班 | BY2: 试产 | BZ2: 早班 | CA2: 中班 | CB2: 晚班 | CC2: 试产
A4: 1400T-6 | B4: B9RL Fender 2K Outer Lens Left sde | C4: L755405 | D4: 6.9H | E4: 100 | F4: 0.85 | G4: 46307 | H4: ORD_SY38_L755390S_1022 | I4: 210 | J4: 210
A5: 1400T-6 | B5: BMW G58 箱灯透镜右 | C5: LAC3181 | D5: 3.0H | E5: 60 | F5: 0.85 | G5: 46307.286 | H5: ORD_SY38_LCC4725ZN04_1022 | I5: 150 | J5: 150
A6: 1400T-6 | B6: B9RL Fender 2K Outer Lens Left sde | C6: L755405 | D6: 13.7H | E6: 100 | F6: 0.85 | G6: 46307.409 | H6: ORD_SY38_L755390S_1019 | I6: 420 | J6: 66.771845 | L6: 353.22816
A7: 1400T-6 | B7: B9RL Trunk 2K Outer Lens | C7: L755774 | D7: 7.1H | E7: 90 | F7: 0.85 | G7: 46307.981 | H7: ORD_SY38_L755548S_1022 | I7: 240 | L7: 15.283019 | N7: 224.71698
A8: 1400T-6 | B8: B9RL Fender 2K Outer Lens Left sde | C8: L755405 | D8: 4.6H | E8: 100 | F8: 0.85 | G8: 46308.276 | H8: ORD_SY38_L755390S_1016 | I8: 140 | N8: 140
A9: 1400T-6 | B9: BMW G58 箱灯透镜左 | C9: LAC3180 | D9: 3.0H | E9: 60 | F9: 0.85 | G9: 46308.467 | H9: ORD_SY38_LCC4710ZN04_1022 | I9: 150 | N9: 40.677966 | P9: 109.32203
A10: 1400T-6 | B10: B9RL Fender 2K Outer Lens Right sde | C10: L782264 | D10: 6.9H | E10: 100 | F10: 0.85 | G10: 46308.59 | H10: ORD_SY38_L755392S_1022 | I10: 210 | P10: 210
A11: 1400T-6 | B11: B9RL Fender 2K Outer Lens Right sde | C11: L782264 | D11: 13.7H | E11: 100 | F11: 0.85 | G11: 46308.876 | H11: ORD_SY38_L755392S_1019 | I11: 420 | P11: 91.237864 | R11: 328.76214
A12: 1400T-6 | B12: B9RL Trunk 2K Outer Lens | C12: L755774 | D12: 11.3H | E12: 90 | F12: 0.85 | G12: 46309.448 | H12: ORD_SY38_L755548S_1019 | I12: 384 | R12: 42.477876 | T12: 341.52212
A13: 1400T-6 | B13: B9RL Trunk 2K Outer Lens | C13: L755774 | D13: 3.5H | E13: 90 | F13: 0.85 | G13: 46309.919 | H13: ORD_SY38_L755548S_1016 | I13: 120 | T13: 66.226415 | V13: 53.773585
A14: 1400T-6 | B14: B9RL Fender 2K Outer Lens Right sde | C14: L782264 | D14: 4.6H | E14: 100 | F14: 0.85 | G14: 46310.066 | H14: ORD_SY38_L755392S_1016 | I14: 140 | V14: 140
A15: 1400T-6 | B15: B9RL Trunk 2K Outer Lens | C15: L755774 | D15: 14.8H | E15: 90 | F15: 0.85 | G15: 46310.257 | H15: ORD_SY38_L755548S_1017 | I15: 504 | V15: 198.20225 | X15: 305.79775
A16: 1400T-6 | B16: B9RL Fender 2K Outer Lens Left sde | C16: L755405 | D16: 16.0H | E16: 100 | F16: 0.85 | G16: 46310.875 | H16: ORD_SY38_L755390S_1017 | I16: 490 | X16: 91.779396 | Z16: 367.11759 | AB16: 31.103018
A17: 1400T-6 | B17: B9RL Fender 2K Outer Lens Right sde | C17: L782264 | D17: 16.0H | E17: 100 | F17: 0.85 | G17: 46311.542 | H17: ORD_SY38_L755392S_1017 | I17: 490 | AB17: 336.01457 | AD17: 153.98543
E19: 1280 | I19: 4068 | J19: 426.77184 | L19: 368.51117 | N19: 405.39495 | P19: 410.5599 | R19: 371.24001 | T19: 407.74854 | V19: 391.97583 | X19: 397.57715 | Z19: 367.11759 | AB19: 367.11759 | AD19: 153.98543
A21: PGLINKAGE | B21: CX11 LHD传动杆总成（新） | C21: WB80510 | D21: 2.5H | E21: 44 | F21: 0.71 | G21: 46307 | H21: ORD_WL_WB80510_1014 | I21: 144 | J21: 144
A22: PGLINKAGE | B22: CX11 LHD传动杆总成（新） | C22: WB80510 | D22: 2.5H | E22: 44 | F22: 0.71 | G22: 46307.103 | H22: ORD_WL_WB80510_1019 | I22: 144 | J22: 144
A23: PGLINKAGE | B23: CX11 LHD传动杆总成（新） | C23: WB80510 | D23: 2.5H | E23: 44 | F23: 0.71 | G23: 46307.207 | H23: ORD_WL_WB80510_1016 | I23: 144 | J23: 144
A24: PGLINKAGE | B24: L743 传动杆总成 | C24: WD48696 | D24: 3.0H | E24: 42 | F24: 0.71 | G24: 46307.467 | H24: ORD_WL_WD48696_1019 | I24: 180 | K24: 180
A25: PGLINKAGE | B25: Chery KP31 LHD 传动杆 | C25: WCA1894 | D25: 3.2H | E25: 46 | F25: 0.71 | G25: 46307.601 | H25: ORD_WL_WCA1894_1017 | I25: 180 | K25: 87.692308 | L25: 92.307692
A26: PGLINKAGE | B26: LEAP CU1207&1307 传动杆总成-三厂 | C26: WBC9317C | D26: 12.0H | E26: 32 | F26: 0.71 | G26: 46308.228 | H26: ORD_WL_WBC9317C_1013 | I26: 960 | N26: 200.77562 | O26: 638.22715 | P26: 120.99723
A27: PGLINKAGE | B27: Chery KP31 RHD 传动杆 | C27: WCB8574 | D27: 13.4H | E27: 46 | F27: 0.71 | G27: 46309.095 | H27: ORD_WL_WCB8574_1017 | I27: 745 | R27: 317.43478 | S27: 427.56522
A28: PGLINKAGE | B28: 930B传动杆总成 | C28: WB35356 | D28: 25.2H | E28: 43 | F28: 0.71 | G28: 46309.688 | H28: ORD_WL_WB35356_1015 | I28: 1500 | T28: 445.54455 | V28: 475.24752 | W28: 475.24752 | X28: 103.9604
A29: PGLINKAGE | B29: E371传动杆总成 | C29: WD59238 | D29: 3.2H | E29: 42 | F29: 0.71 | G29: 46310.74 | H29: ORD_WL_WD59238_1019 | I29: 192 | X29: 192
A30: PGLINKAGE | B30: DX11电机连杆总成(新） | C30: WCF8126 | D30: 8.6H | E30: 38 | F30: 0.71 | G30: 46310.872 | H30: ORD_WL_WCF8126_1019 | I30: 576 | X30: 207.31518 | Z30: 368.68482
A31: PGLINKAGE | B31: DX11电机连杆总成(新） | C31: WCF8126 | D31: 8.6H | E31: 38 | F31: 0.71 | G31: 46311.347 | H31: ORD_WL_WCF8126_1022 | I31: 576 | AA31: 515.48638 | AB31: 60.513619
A32: PGLINKAGE | B32: LEAP CU1207&1307 传动杆总成-三厂 | C32: WBC9317C | D32: 12.8H | E32: 32 | F32: 0.71 | G32: 46311.722 | H32: ORD_WL_WBC9317C_1019 | I32: 1020 | AB32: 531.94263 | AD32: 488.05737
A33: PGLINKAGE | B33: LEAP CU1207&1307 传动杆总成 | C33: WBC9317 | D33: 21.6H | E33: 46 | F33: 0.71 | G33: 46312.606 | H33: ORD_WL_WBC9317_1022 | I33: 1200 | AE33: 81.481481 | AF33: 444.44444 | AH33: 444.44444 | AI33: 229.62963
A34: PGLINKAGE | B34: E371 A1 传动杆总成 | C34: WAB6404 | D34: 2.2H | E34: 46 | F34: 0.71 | G34: 46313.506 | H34: ORD_WL_WAB6404_1021 | I34: 122 | AI34: 122
A35: PGLINKAGE | B35: LEAP CU1207&1307 传动杆总成-三厂 | C35: WBC9317C | D35: 6.0H | E35: 32 | F35: 0.71 | G35: 46313.597 | H35: ORD_WL_WBC9317C_1022 | I35: 480 | AI35: 132.96399 | AJ35: 347.03601
A36: PGLINKAGE | B36: L743 传动杆总成 | C36: WD48696 | D36: 5.9H | E36: 42 | F36: 0.71 | G36: 46313.894 | H36: ORD_WL_WD48696_1022 | I36: 360 | AJ36: 154.14085 | AL36: 205.85915
A37: PGLINKAGE | B37: LEAP CU1207&1307 传动杆总成-三厂 | C37: WBC9317C | D37: 10.5H | E37: 32 | F37: 0.71 | G37: 46314.141 | H37: ORD_WL_WBC9317C_1021 | I37: 840 | AL37: 368.74802 | AM37: 471.25198
A38: PGLINKAGE | B38: LEAP CU1207&1307 传动杆总成 | C38: WBC9317 | D38: 21.6H | E38: 46 | F38: 0.71 | G38: 46314.579 | H38: ORD_WL_WBC9317_1020 | I38: 1200 | AM38: 116.66667 | AN38: 444.44444 | AP38: 444.44444 | AQ38: 194.44444
A39: PGLINKAGE | B39: 930B传动杆总成 | C39: WB35356 | D39: 113.1H | E39: 43 | F39: 0.71 | G39: 46319.644 | H39: ORD_WL_WB35356_1020 | I39: 6720 | BG39: 31.698113 | BH39: 475.4717 | BJ39: 475.4717 | BK39: 475.4717 | BL39: 475.4717 | BN39: 475.4717 | BO39: 475.4717 | BP39: 475.4717 | BR39: 475.4717 | BS39: 475.4717 | BT39: 475.4717 | BV39: 475.4717 | BW39: 475.4717 | BX39: 475.4717 | BZ39: 475.4717 | CA39: 31.698113
E41: 778 | I41: 17283 | J41: 432 | K41: 267.69231 | L41: 92.307692 | N41: 200.77562 | O41: 638.22715 | P41: 120.99723 | R41: 317.43478 | S41: 427.56522 | T41: 445.54455 | V41: 475.24752 | W41: 475.24752 | X41: 503.27557 | Z41: 368.68482 | AA41: 515.48638 | AB41: 592.45625 | AD41: 488.05737 | AE41: 81.481481 | AF41: 444.44444 | AH41: 444.44444 | AI41: 484.59362 | AJ41: 501.17686 | AL41: 574.60717 | AM41: 587.91865 | AN41: 444.44444 | AP41: 444.44444 | AQ41: 194.44444 | BG41: 31.698113 | BH41: 475.4717 | BJ41: 475.4717 | BK41: 475.4717 | BL41: 475.4717 | BN41: 475.4717 | BO41: 475.4717 | BP41: 475.4717 | BR41: 475.4717 | BS41: 475.4717 | BT41: 475.4717 | BV41: 475.4717 | BW41: 475.4717 | BX41: 475.4717 | BZ41: 475.4717 | CA41: 31.698113
A43: PU07 | B43: B9 Low Fender L | C43: L755390S | D43: 2.4H | E43: 35 | F43: 0.85 | G43: 46307.286 | H43: ORD_SY38_L755390S_1022 | I43: 210 | J43: 210
A44: PU07 | B44: B9 Low Fender L | C44: L755390S | D44: 4.8H | E44: 35 | F44: 0.85 | G44: 46307.981 | H44: ORD_SY38_L755390S_1019 | I44: 420 | L44: 39.238754 | N44: 380.76125
A45: PU07 | B45: B9 High Trunk | C45: L755548S | D45: 5.5H | E45: 70 | F45: 0.85 | G45: 46308.276 | H45: ORD_SY38_L755548S_1022 | I45: 240 | N45: 234.90909 | P45: 5.090909
...
